[2025-07-02T04:17:13.136+0000] {taskinstance.py:1956} INFO - Dependencies all met for dep_context=non-requeueable deps ti=<TaskInstance: weather_pipeline.fetch_weather manual__2025-07-02T04:16:10.041832+00:00 [queued]>
[2025-07-02T04:17:13.143+0000] {taskinstance.py:1956} INFO - Dependencies all met for dep_context=requeueable deps ti=<TaskInstance: weather_pipeline.fetch_weather manual__2025-07-02T04:16:10.041832+00:00 [queued]>
[2025-07-02T04:17:13.143+0000] {taskinstance.py:2170} INFO - Starting attempt 2 of 2
[2025-07-02T04:17:13.291+0000] {taskinstance.py:2191} INFO - Executing <Task(PythonOperator): fetch_weather> on 2025-07-02 04:16:10.041832+00:00
[2025-07-02T04:17:13.298+0000] {standard_task_runner.py:60} INFO - Started process 610 to run task
[2025-07-02T04:17:13.302+0000] {standard_task_runner.py:87} INFO - Running: ['airflow', 'tasks', 'run', 'weather_pipeline', 'fetch_weather', 'manual__2025-07-02T04:16:10.041832+00:00', '--job-id', '18', '--raw', '--subdir', 'DAGS_FOLDER/weather_pipline.py', '--cfg-path', '/tmp/tmp5ozt6xme']
[2025-07-02T04:17:13.304+0000] {standard_task_runner.py:88} INFO - Job 18: Subtask fetch_weather
[2025-07-02T04:17:13.320+0000] {logging_mixin.py:188} WARNING - /home/airflow/.local/lib/python3.8/site-packages/airflow/settings.py:194 DeprecationWarning: The sql_alchemy_conn option in [core] has been moved to the sql_alchemy_conn option in [database] - the old setting has been used, but please update your config.
[2025-07-02T04:17:13.349+0000] {task_command.py:423} INFO - Running <TaskInstance: weather_pipeline.fetch_weather manual__2025-07-02T04:16:10.041832+00:00 [running]> on host 6b14fa6e4bb8
[2025-07-02T04:17:13.418+0000] {taskinstance.py:2480} INFO - Exporting env vars: AIRFLOW_CTX_DAG_OWNER='***' AIRFLOW_CTX_DAG_ID='weather_pipeline' AIRFLOW_CTX_TASK_ID='fetch_weather' AIRFLOW_CTX_EXECUTION_DATE='2025-07-02T04:16:10.041832+00:00' AIRFLOW_CTX_TRY_NUMBER='2' AIRFLOW_CTX_DAG_RUN_ID='manual__2025-07-02T04:16:10.041832+00:00'
[2025-07-02T04:17:13.895+0000] {taskinstance.py:2698} ERROR - Task failed with exception
Traceback (most recent call last):
  File "/home/airflow/.local/lib/python3.8/site-packages/airflow/models/taskinstance.py", line 433, in _execute_task
    result = execute_callable(context=context, **execute_callable_kwargs)
  File "/home/airflow/.local/lib/python3.8/site-packages/airflow/operators/python.py", line 199, in execute
    return_value = self.execute_callable()
  File "/home/airflow/.local/lib/python3.8/site-packages/airflow/operators/python.py", line 216, in execute_callable
    return self.python_callable(*self.op_args, **self.op_kwargs)
  File "/opt/airflow/dags/weather_pipline.py", line 32, in fetch_weather
    'temp': data['main']['temp'],
KeyError: 'main'
[2025-07-02T04:17:13.903+0000] {taskinstance.py:1138} INFO - Marking task as FAILED. dag_id=weather_pipeline, task_id=fetch_weather, execution_date=20250702T041610, start_date=20250702T041713, end_date=20250702T041713
[2025-07-02T04:17:13.915+0000] {standard_task_runner.py:107} ERROR - Failed to execute job 18 for task fetch_weather ('main'; 610)
[2025-07-02T04:17:13.934+0000] {local_task_job_runner.py:234} INFO - Task exited with return code 1
[2025-07-02T04:17:13.952+0000] {taskinstance.py:3280} INFO - 0 downstream tasks scheduled from follow-on schedule check
