[2025-07-02T03:46:17.646+0000] {taskinstance.py:1956} INFO - Dependencies all met for dep_context=non-requeueable deps ti=<TaskInstance: weather_pipeline.fetch_weather manual__2025-07-02T03:46:16.586075+00:00 [queued]>
[2025-07-02T03:46:17.652+0000] {taskinstance.py:1956} INFO - Dependencies all met for dep_context=requeueable deps ti=<TaskInstance: weather_pipeline.fetch_weather manual__2025-07-02T03:46:16.586075+00:00 [queued]>
[2025-07-02T03:46:17.653+0000] {taskinstance.py:2170} INFO - Starting attempt 1 of 2
[2025-07-02T03:46:17.664+0000] {taskinstance.py:2191} INFO - Executing <Task(PythonOperator): fetch_weather> on 2025-07-02 03:46:16.586075+00:00
[2025-07-02T03:46:17.671+0000] {standard_task_runner.py:60} INFO - Started process 685 to run task
[2025-07-02T03:46:17.675+0000] {standard_task_runner.py:87} INFO - Running: ['airflow', 'tasks', 'run', 'weather_pipeline', 'fetch_weather', 'manual__2025-07-02T03:46:16.586075+00:00', '--job-id', '4', '--raw', '--subdir', 'DAGS_FOLDER/weather_pipline.py', '--cfg-path', '/tmp/tmpxy_iyqxn']
[2025-07-02T03:46:17.884+0000] {standard_task_runner.py:88} INFO - Job 4: Subtask fetch_weather
[2025-07-02T03:46:17.900+0000] {logging_mixin.py:188} WARNING - /home/airflow/.local/lib/python3.8/site-packages/airflow/settings.py:194 DeprecationWarning: The sql_alchemy_conn option in [core] has been moved to the sql_alchemy_conn option in [database] - the old setting has been used, but please update your config.
[2025-07-02T03:46:17.931+0000] {task_command.py:423} INFO - Running <TaskInstance: weather_pipeline.fetch_weather manual__2025-07-02T03:46:16.586075+00:00 [running]> on host 145d21cdda3a
[2025-07-02T03:46:17.996+0000] {taskinstance.py:2480} INFO - Exporting env vars: AIRFLOW_CTX_DAG_OWNER='***' AIRFLOW_CTX_DAG_ID='weather_pipeline' AIRFLOW_CTX_TASK_ID='fetch_weather' AIRFLOW_CTX_EXECUTION_DATE='2025-07-02T03:46:16.586075+00:00' AIRFLOW_CTX_TRY_NUMBER='1' AIRFLOW_CTX_DAG_RUN_ID='manual__2025-07-02T03:46:16.586075+00:00'
[2025-07-02T03:46:18.450+0000] {taskinstance.py:2698} ERROR - Task failed with exception
Traceback (most recent call last):
  File "/home/airflow/.local/lib/python3.8/site-packages/airflow/models/taskinstance.py", line 433, in _execute_task
    result = execute_callable(context=context, **execute_callable_kwargs)
  File "/home/airflow/.local/lib/python3.8/site-packages/airflow/operators/python.py", line 199, in execute
    return_value = self.execute_callable()
  File "/home/airflow/.local/lib/python3.8/site-packages/airflow/operators/python.py", line 216, in execute_callable
    return self.python_callable(*self.op_args, **self.op_kwargs)
  File "/opt/airflow/dags/weather_pipline.py", line 34, in fetch_weather
    df.to_csv('/opt/airflow/dags/weather_data.csv', mode='a', header=False, index=False)
  File "/home/airflow/.local/lib/python3.8/site-packages/pandas/core/generic.py", line 3772, in to_csv
    return DataFrameRenderer(formatter).to_csv(
  File "/home/airflow/.local/lib/python3.8/site-packages/pandas/io/formats/format.py", line 1186, in to_csv
    csv_formatter.save()
  File "/home/airflow/.local/lib/python3.8/site-packages/pandas/io/formats/csvs.py", line 240, in save
    with get_handle(
  File "/home/airflow/.local/lib/python3.8/site-packages/pandas/io/common.py", line 859, in get_handle
    handle = open(
PermissionError: [Errno 13] Permission denied: '/opt/airflow/dags/weather_data.csv'
[2025-07-02T03:46:18.463+0000] {taskinstance.py:1138} INFO - Marking task as UP_FOR_RETRY. dag_id=weather_pipeline, task_id=fetch_weather, execution_date=20250702T034616, start_date=20250702T034617, end_date=20250702T034618
[2025-07-02T03:46:18.476+0000] {standard_task_runner.py:107} ERROR - Failed to execute job 4 for task fetch_weather ([Errno 13] Permission denied: '/opt/airflow/dags/weather_data.csv'; 685)
[2025-07-02T03:46:18.516+0000] {local_task_job_runner.py:234} INFO - Task exited with return code 1
[2025-07-02T03:46:18.677+0000] {taskinstance.py:3280} INFO - 0 downstream tasks scheduled from follow-on schedule check
