[2025-07-02T03:47:19.854+0000] {taskinstance.py:1956} INFO - Dependencies all met for dep_context=non-requeueable deps ti=<TaskInstance: weather_pipeline.fetch_weather manual__2025-07-02T03:46:16.586075+00:00 [queued]>
[2025-07-02T03:47:19.860+0000] {taskinstance.py:1956} INFO - Dependencies all met for dep_context=requeueable deps ti=<TaskInstance: weather_pipeline.fetch_weather manual__2025-07-02T03:46:16.586075+00:00 [queued]>
[2025-07-02T03:47:19.861+0000] {taskinstance.py:2170} INFO - Starting attempt 2 of 2
[2025-07-02T03:47:19.872+0000] {taskinstance.py:2191} INFO - Executing <Task(PythonOperator): fetch_weather> on 2025-07-02 03:46:16.586075+00:00
[2025-07-02T03:47:19.879+0000] {standard_task_runner.py:60} INFO - Started process 710 to run task
[2025-07-02T03:47:19.882+0000] {standard_task_runner.py:87} INFO - Running: ['airflow', 'tasks', 'run', 'weather_pipeline', 'fetch_weather', 'manual__2025-07-02T03:46:16.586075+00:00', '--job-id', '5', '--raw', '--subdir', 'DAGS_FOLDER/weather_pipline.py', '--cfg-path', '/tmp/tmp_zvg3hbv']
[2025-07-02T03:47:20.131+0000] {standard_task_runner.py:88} INFO - Job 5: Subtask fetch_weather
[2025-07-02T03:47:20.145+0000] {logging_mixin.py:188} WARNING - /home/airflow/.local/lib/python3.8/site-packages/airflow/settings.py:194 DeprecationWarning: The sql_alchemy_conn option in [core] has been moved to the sql_alchemy_conn option in [database] - the old setting has been used, but please update your config.
[2025-07-02T03:47:20.175+0000] {task_command.py:423} INFO - Running <TaskInstance: weather_pipeline.fetch_weather manual__2025-07-02T03:46:16.586075+00:00 [running]> on host 145d21cdda3a
[2025-07-02T03:47:20.246+0000] {taskinstance.py:2480} INFO - Exporting env vars: AIRFLOW_CTX_DAG_OWNER='***' AIRFLOW_CTX_DAG_ID='weather_pipeline' AIRFLOW_CTX_TASK_ID='fetch_weather' AIRFLOW_CTX_EXECUTION_DATE='2025-07-02T03:46:16.586075+00:00' AIRFLOW_CTX_TRY_NUMBER='2' AIRFLOW_CTX_DAG_RUN_ID='manual__2025-07-02T03:46:16.586075+00:00'
[2025-07-02T03:47:20.697+0000] {taskinstance.py:2698} ERROR - Task failed with exception
Traceback (most recent call last):
  File "/home/airflow/.local/lib/python3.8/site-packages/airflow/models/taskinstance.py", line 433, in _execute_task
    result = execute_callable(context=context, **execute_callable_kwargs)
  File "/home/airflow/.local/lib/python3.8/site-packages/airflow/operators/python.py", line 199, in execute
    return_value = self.execute_callable()
  File "/home/airflow/.local/lib/python3.8/site-packages/airflow/operators/python.py", line 216, in execute_callable
    return self.python_callable(*self.op_args, **self.op_kwargs)
  File "/opt/airflow/dags/weather_pipline.py", line 34, in fetch_weather
    df.to_csv('/opt/airflow/dags/weather_data.csv', mode='a', header=False, index=False)
  File "/home/airflow/.local/lib/python3.8/site-packages/pandas/core/generic.py", line 3772, in to_csv
    return DataFrameRenderer(formatter).to_csv(
  File "/home/airflow/.local/lib/python3.8/site-packages/pandas/io/formats/format.py", line 1186, in to_csv
    csv_formatter.save()
  File "/home/airflow/.local/lib/python3.8/site-packages/pandas/io/formats/csvs.py", line 240, in save
    with get_handle(
  File "/home/airflow/.local/lib/python3.8/site-packages/pandas/io/common.py", line 859, in get_handle
    handle = open(
PermissionError: [Errno 13] Permission denied: '/opt/airflow/dags/weather_data.csv'
[2025-07-02T03:47:20.709+0000] {taskinstance.py:1138} INFO - Marking task as FAILED. dag_id=weather_pipeline, task_id=fetch_weather, execution_date=20250702T034616, start_date=20250702T034719, end_date=20250702T034720
[2025-07-02T03:47:20.718+0000] {standard_task_runner.py:107} ERROR - Failed to execute job 5 for task fetch_weather ([Errno 13] Permission denied: '/opt/airflow/dags/weather_data.csv'; 710)
[2025-07-02T03:47:20.761+0000] {local_task_job_runner.py:234} INFO - Task exited with return code 1
[2025-07-02T03:47:20.924+0000] {taskinstance.py:3280} INFO - 0 downstream tasks scheduled from follow-on schedule check
