[2025-07-02T04:22:20.827+0000] {taskinstance.py:1956} INFO - Dependencies all met for dep_context=non-requeueable deps ti=<TaskInstance: weather_pipeline.fetch_weather manual__2025-07-02T04:22:19.406987+00:00 [queued]>
[2025-07-02T04:22:20.834+0000] {taskinstance.py:1956} INFO - Dependencies all met for dep_context=requeueable deps ti=<TaskInstance: weather_pipeline.fetch_weather manual__2025-07-02T04:22:19.406987+00:00 [queued]>
[2025-07-02T04:22:20.835+0000] {taskinstance.py:2170} INFO - Starting attempt 1 of 2
[2025-07-02T04:22:20.982+0000] {taskinstance.py:2191} INFO - Executing <Task(PythonOperator): fetch_weather> on 2025-07-02 04:22:19.406987+00:00
[2025-07-02T04:22:20.989+0000] {standard_task_runner.py:60} INFO - Started process 735 to run task
[2025-07-02T04:22:20.992+0000] {standard_task_runner.py:87} INFO - Running: ['airflow', 'tasks', 'run', 'weather_pipeline', 'fetch_weather', 'manual__2025-07-02T04:22:19.406987+00:00', '--job-id', '21', '--raw', '--subdir', 'DAGS_FOLDER/weather_pipline.py', '--cfg-path', '/tmp/tmps0bqzy1g']
[2025-07-02T04:22:20.994+0000] {standard_task_runner.py:88} INFO - Job 21: Subtask fetch_weather
[2025-07-02T04:22:21.011+0000] {logging_mixin.py:188} WARNING - /home/airflow/.local/lib/python3.8/site-packages/airflow/settings.py:194 DeprecationWarning: The sql_alchemy_conn option in [core] has been moved to the sql_alchemy_conn option in [database] - the old setting has been used, but please update your config.
[2025-07-02T04:22:21.046+0000] {task_command.py:423} INFO - Running <TaskInstance: weather_pipeline.fetch_weather manual__2025-07-02T04:22:19.406987+00:00 [running]> on host 6b14fa6e4bb8
[2025-07-02T04:22:21.116+0000] {taskinstance.py:2480} INFO - Exporting env vars: AIRFLOW_CTX_DAG_OWNER='***' AIRFLOW_CTX_DAG_ID='weather_pipeline' AIRFLOW_CTX_TASK_ID='fetch_weather' AIRFLOW_CTX_EXECUTION_DATE='2025-07-02T04:22:19.406987+00:00' AIRFLOW_CTX_TRY_NUMBER='1' AIRFLOW_CTX_DAG_RUN_ID='manual__2025-07-02T04:22:19.406987+00:00'
[2025-07-02T04:22:21.523+0000] {logging_mixin.py:188} INFO - {'cod': 401, 'message': 'Invalid API key. Please see https://openweathermap.org/faq#error401 for more info.'}
[2025-07-02T04:22:21.524+0000] {taskinstance.py:2698} ERROR - Task failed with exception
Traceback (most recent call last):
  File "/home/airflow/.local/lib/python3.8/site-packages/airflow/models/taskinstance.py", line 433, in _execute_task
    result = execute_callable(context=context, **execute_callable_kwargs)
  File "/home/airflow/.local/lib/python3.8/site-packages/airflow/operators/python.py", line 199, in execute
    return_value = self.execute_callable()
  File "/home/airflow/.local/lib/python3.8/site-packages/airflow/operators/python.py", line 216, in execute_callable
    return self.python_callable(*self.op_args, **self.op_kwargs)
  File "/opt/airflow/dags/weather_pipline.py", line 33, in fetch_weather
    'temp': data['main']['temp'],
KeyError: 'main'
[2025-07-02T04:22:21.531+0000] {taskinstance.py:1138} INFO - Marking task as UP_FOR_RETRY. dag_id=weather_pipeline, task_id=fetch_weather, execution_date=20250702T042219, start_date=20250702T042220, end_date=20250702T042221
[2025-07-02T04:22:21.541+0000] {standard_task_runner.py:107} ERROR - Failed to execute job 21 for task fetch_weather ('main'; 735)
[2025-07-02T04:22:21.579+0000] {local_task_job_runner.py:234} INFO - Task exited with return code 1
[2025-07-02T04:22:21.597+0000] {taskinstance.py:3280} INFO - 0 downstream tasks scheduled from follow-on schedule check
